<?xml version="1.0" encoding="utf-8"?>
<!-- This URDF was automatically created by SolidWorks to URDF Exporter! Originally created by Stephen Brawner (brawner@gmail.com) 
     Commit Version: 1.6.0-4-g7f85cfe  Build Version: 1.6.7995.38578
     For more information, please see http://wiki.ros.org/sw_urdf_exporter 
     time:2024.8.15   writer:MYH
     limit without inertia matrix
     -->
     
<robot
  name="ARM002">
  <link
    name="base_link">
    <inertial>
      <origin
        xyz="-8.2373E-10 0.0173 1.2822E-09"
        rpy="0 0 0" />
      <mass
        value="0.40004" />
      <inertia
        ixx="0.00051597"
        ixy="-2.8373E-12"
        ixz="1.0588E-11"
        iyy="0.00040078"
        iyz="-3.9889E-12"
        izz="0.00058577" />
    </inertial>
    <visual>
      <origin
        xyz="0 0 0"
        rpy="0 0 0" />
      <geometry>
        <mesh
          filename="package://wow_description/ARM002/meshes/base_link.STL" />
      </geometry>
      <material
        name="">
        <color
          rgba="1 1 1 1" />
      </material>
    </visual>
    <collision>
      <origin
        xyz="0 0 0"
        rpy="0 0 0" />
      <geometry>
        <mesh
          filename="package://wow_description/ARM002/meshes/base_link.STL" />
      </geometry>
    </collision>
  </link>
  <link
    name="left_shoulder_pitch_link">
    <inertial>
      <origin
        xyz="-0.0027091 0.041048 1.7482E-08"
        rpy="0 0 0" />
      <mass
        value="0.2886" />
      <inertia
        ixx="0.00040419"
        ixy="2.2651E-05"
        ixz="-4.5758E-09"
        iyy="0.00057229"
        iyz="-8.9463E-10"
        izz="0.00073434" />
    </inertial>
    <visual>
      <origin
        xyz="0 0 0"
        rpy="0 0 0" />
      <geometry>
        <mesh
          filename="package://wow_description/ARM002/meshes/left_shoulder_pitch_link.STL" />
      </geometry>
      <material
        name="">
        <color
          rgba="0.66667 0.69804 0.76863 1" />
      </material>
    </visual>
    <collision>
      <origin
        xyz="0 0 0"
        rpy="0 0 0" />
      <geometry>
        <mesh
          filename="package://wow_description/ARM002/meshes/left_shoulder_pitch_link.STL" />
      </geometry>
    </collision>
  </link>
  <joint
    name="left_shoulder_pitch_joint"
    type="revolute">
    <origin
      xyz="0 0.0611 0"
      rpy="0 0 0" />
    <parent
      link="base_link" />
    <child
      link="left_shoulder_pitch_link" />
    <axis
      xyz="0 -1 0" />
    <limit
      lower="-1.5"
      upper="1.5"
      effort="52.8"
      velocity="41" />
  </joint>
  <link
    name="left_shoulder_roll_link">
    <inertial>
      <origin
        xyz="0.00062227 0.0056648 -0.026298"
        rpy="0 0 0" />
      <mass
        value="0.66777" />
      <inertia
        ixx="0.00076087"
        ixy="-1.7481E-05"
        ixz="5.7607E-05"
        iyy="0.00089339"
        iyz="-5.2607E-05"
        izz="0.00076022" />
    </inertial>
    <visual>
      <origin
        xyz="0 0 0"
        rpy="0 0 0" />
      <geometry>
        <mesh
          filename="package://wow_description/ARM002/meshes/left_shoulder_roll_link.STL" />
      </geometry>
      <material
        name="">
        <color
          rgba="1 1 1 1" />
      </material>
    </visual>
    <collision>
      <origin
        xyz="0 0 0"
        rpy="0 0 0" />
      <geometry>
        <mesh
          filename="package://wow_description/ARM002/meshes/left_shoulder_roll_link.STL" />
      </geometry>
    </collision>
  </link>
  <joint
    name="left_shoulder_roll_joint"
    type="revolute">
    <origin
      xyz="0 0.07 0"
      rpy="0 0 0" />
    <parent
      link="left_shoulder_pitch_link" />
    <child
      link="left_shoulder_roll_link" />
    <axis
      xyz="-1 0 0" />
    <limit
      lower="-1.75"
      upper="0.75"
      effort="52.8"
      velocity="41" />
  </joint>
  <link
    name="left_shoulder_yaw_link">
    <inertial>
      <origin
        xyz="-0.00054921 0.0025822 -0.092103"
        rpy="0 0 0" />
      <mass
        value="0.43104" />
      <inertia
        ixx="0.00052037"
        ixy="-2.5306E-05"
        ixz="-3.5334E-06"
        iyy="0.00051904"
        iyz="4.0574E-05"
        izz="0.00040492" />
    </inertial>
    <visual>
      <origin
        xyz="0 0 0"
        rpy="0 0 0" />
      <geometry>
        <mesh
          filename="package://wow_description/ARM002/meshes/left_shoulder_yaw_link.STL" />
      </geometry>
      <material
        name="">
        <color
          rgba="0.66667 0.69804 0.76863 1" />
      </material>
    </visual>
    <collision>
      <origin
        xyz="0 0 0"
        rpy="0 0 0" />
      <geometry>
        <mesh
          filename="package://wow_description/ARM002/meshes/left_shoulder_yaw_link.STL" />
      </geometry>
    </collision>
  </link>
  <joint
    name="left_shoulder_yaw_joint"
    type="revolute">
    <origin
      xyz="0 0.009 -0.1264"
      rpy="0 0 0" />
    <parent
      link="left_shoulder_roll_link" />
    <child
      link="left_shoulder_yaw_link" />
    <axis
      xyz="0 0 -1" />
    <limit
      lower="-1.5"
      upper="1.5"
      effort="28.8"
      velocity="49" />
  </joint>
  <link
    name="left_elbow_pitch_link">
    <inertial>
      <origin
        xyz="-0.013674 -0.0014033 -0.042151"
        rpy="0 0 0" />
      <mass
        value="0.66746" />
      <inertia
        ixx="0.0013044"
        ixy="1.64E-06"
        ixz="-0.00011208"
        iyy="0.0014857"
        iyz="4.0826E-06"
        izz="0.0003813" />
    </inertial>
    <visual>
      <origin
        xyz="0 0 0"
        rpy="0 0 0" />
      <geometry>
        <mesh
          filename="package://wow_description/ARM002/meshes/left_elbow_pitch_link.STL" />
      </geometry>
      <material
        name="">
        <color
          rgba="1 1 1 1" />
      </material>
    </visual>
    <collision>
      <origin
        xyz="0 0 0"
        rpy="0 0 0" />
      <geometry>
        <mesh
          filename="package://wow_description/ARM002/meshes/left_elbow_pitch_link.STL" />
      </geometry>
    </collision>
  </link>
  <joint
    name="left_elbow_pitch_joint"
    type="revolute">
    <origin
      xyz="0.0205 0 -0.1486"
      rpy="0 0 0" />
    <parent
      link="left_shoulder_yaw_link" />
    <child
      link="left_elbow_pitch_link" />
    <axis
      xyz="0 -1 0" />
    <limit
      lower="-0"
      upper="2.5"
      effort="28.8"
      velocity="49" />
  </joint>
  <link
    name="left_wrist_yaw_link">
    <inertial>
      <origin
        xyz="2.0709E-07 0.0049137 -0.013518"
        rpy="0 0 0" />
      <mass
        value="0.13897" />
      <inertia
        ixx="7.8532E-05"
        ixy="-6.8246E-10"
        ixz="2.5281E-10"
        iyy="6.1145E-05"
        iyz="1.6045E-05"
        izz="8.1074E-05" />
    </inertial>
    <visual>
      <origin
        xyz="0 0 0"
        rpy="0 0 0" />
      <geometry>
        <mesh
          filename="package://wow_description/ARM002/meshes/left_wrist_yaw_link.STL" />
      </geometry>
      <material
        name="">
        <color
          rgba="0.66667 0.69804 0.76863 1" />
      </material>
    </visual>
    <collision>
      <origin
        xyz="0 0 0"
        rpy="0 0 0" />
      <geometry>
        <mesh
          filename="package://wow_description/ARM002/meshes/left_wrist_yaw_link.STL" />
      </geometry>
    </collision>
  </link>
  <joint
    name="left_wrist_yaw_joint"
    type="revolute">
    <origin
      xyz="-0.0205 0 -0.17"
      rpy="0 0 0" />
    <parent
      link="left_elbow_pitch_link" />
    <child
      link="left_wrist_yaw_link" />
    <axis
      xyz="0 0 -1" />
    <limit
      lower="-1.5"
      upper="1.5"
      effort="8.8"
      velocity="59" />
  </joint>
  <link
    name="left_wrist_pitch_link">
    <inertial>
      <origin
        xyz="0.0016339 0.0058967 -0.010353"
        rpy="0 0 0" />
      <mass
        value="0.29383" />
      <inertia
        ixx="0.00017209"
        ixy="6.7302E-06"
        ixz="4.9877E-06"
        iyy="0.00016372"
        iyz="-1.17E-05"
        izz="0.00018535" />
    </inertial>
    <visual>
      <origin
        xyz="0 0 0"
        rpy="0 0 0" />
      <geometry>
        <mesh
          filename="package://wow_description/ARM002/meshes/left_wrist_pitch_link.STL" />
      </geometry>
      <material
        name="">
        <color
          rgba="1 1 1 1" />
      </material>
    </visual>
    <collision>
      <origin
        xyz="0 0 0"
        rpy="0 0 0" />
      <geometry>
        <mesh
          filename="package://wow_description/ARM002/meshes/left_wrist_pitch_link.STL" />
      </geometry>
    </collision>
  </link>
  <joint
    name="left_wrist_pitch_joint"
    type="revolute">
    <origin
      xyz="0 0 -0.051"
      rpy="0 0 0" />
    <parent
      link="left_wrist_yaw_link" />
    <child
      link="left_wrist_pitch_link" />
    <axis
      xyz="0 1 0" />
    <limit
      lower="-1.15"
      upper="1.15"
      effort="8.8"
      velocity="59" />
  </joint>
  <link
    name="left_wrist_roll_link">
    <inertial>
      <origin
        xyz="0.0017824 -0.00060553 -0.067256"
        rpy="0 0 0" />
      <mass
        value="0.59028" />
      <inertia
        ixx="0.00036166"
        ixy="8.5269E-07"
        ixz="-3.6499E-05"
        iyy="0.00031259"
        iyz="1.275E-06"
        izz="0.00029041" />
    </inertial>
    <visual>
      <origin
        xyz="0 0 0"
        rpy="0 0 0" />
      <geometry>
        <mesh
          filename="package://wow_description/ARM002/meshes/left_wrist_roll_link.STL" />
      </geometry>
      <material
        name="">
        <color
          rgba="0.66667 0.69804 0.76863 1" />
      </material>
    </visual>
    <collision>
      <origin
        xyz="0 0 0"
        rpy="0 0 0" />
      <geometry>
        <mesh
          filename="package://wow_description/ARM002/meshes/left_wrist_roll_link.STL" />
      </geometry>
    </collision>
  </link>
  <joint
    name="left_wrist_roll_joint"
    type="revolute">
    <origin
      xyz="0 0 -0.055"
      rpy="0 0 0" />
    <parent
      link="left_wrist_pitch_link" />
    <child
      link="left_wrist_roll_link" />
    <axis
      xyz="1 0 0" />
    <limit
      lower="-1"
      upper="1"
      effort="8.8"
      velocity="59" />
  </joint>
</robot>